Workbook

Sheet 백로그
A1: No | B1: Epic | C1: Story | D1: 레벨 | E1: 타입 | F1: 이슈 # | G1: 제목 | H1: 상태 | I1: 연결 PR | J1: 부모 # | K1: 링크
A2: 1 | B2: Epic 1 | D2: 1 | E2: Epic | F2: 1 | G2: Epic 1: 크롬 확장 프로그램 - 핵심 데이터 수집 | H2: Closed | K2: #1
A3: 2 | B3: Epic 1 | C3: Story 1-1 | D3: 2 | E3: Story | F3: 2 | G3: Story 1-1: YouTube 재생 영상 ID와 제목을 자동으로 감지할 수 있다 | H3: Closed | J3: 1 | K3: #2
A4: 3 | B4: Epic 1 | C4: Story 1-1 | D4: 3 | E4: Task | F4: 3 | G4: manifest.json 기본 구조 작성 | H4: Closed | J4: 2 | K4: #3
A5: 4 | B5: Epic 1 | C5: Story 1-1 | D5: 3 | E5: Task | F5: 4 | G5: content script, background service worker 파일 뼈대 생성 | H5: Closed | J5: 2 | K5: #4
A6: 5 | B6: Epic 1 | C6: Story 1-1 | D6: 3 | E6: Task | F6: 5 | G6: YouTube URL에서 videoId 파라미터 추출 로직 구현 | H6: Closed | J6: 2 | K6: #5
A7: 6 | B7: Epic 1 | C7: Story 1-1 | D7: 3 | E7: Task | F7: 6 | G7: MutationObserver로 YouTube SPA 페이지 이동 감지 구현 | H7: Closed | J7: 2 | K7: #6
A8: 7 | B8: Epic 1 | C8: Story 1-1 | D8: 3 | E8: Task | F8: 7 | G8: 영상 제목 DOM에서 파싱하는 로직 구현 | H8: Closed | J8: 2 | K8: #7
A9: 8 | B9: Epic 1 | C9: Story 1-1 | D9: 3 | E9: Task | F9: 55 | G9: feat: YouTube 재생 영상 ID와 제목 자동 감지 | H9: Closed | I9: #56 | J9: 2 | K9: #55
A10: 9 | B10: Epic 1 | C10: Story 1-1 | D10: 3 | E10: Bug | F10: 299 | G10: fix: 영상 전환 시 직전 영상 제목이 다음 기록에 붙는 문제 — videoId 확인 강화 및 메타데이터 제목 우선 사용 | H10: Open | J10: 2 | K10: #299
A11: 10 | B11: Epic 1 | C11: Story 1-2 | D11: 2 | E11: Story | F11: 8 | G11: Story 1-2: 감지된 영상 데이터를 세션 단위로 로컬에 저장할 수 있다 | H11: Closed | J11: 1 | K11: #8
A12: 11 | B12: Epic 1 | C12: Story 1-2 | D12: 3 | E12: Task | F12: 9 | G12: chrome.storage.local 저장 데이터 구조 설계 및 구현 | H12: Closed | J12: 8 | K12: #9
A13: 12 | B13: Epic 1 | C13: Story 1-2 | D13: 3 | E13: Task | F13: 10 | G13: 중복 videoId 방지 로직 구현 | H13: Closed | J13: 8 | K13: #10
A14: 13 | B14: Epic 1 | C14: Story 1-2 | D14: 3 | E14: Task | F14: 11 | G14: 저장/조회/초기화 유틸 함수 모듈화 | H14: Closed | J14: 8 | K14: #11
A15: 14 | B15: Epic 1 | C15: Story 1-2 | D15: 3 | E15: Task | F15: 57 | G15: feat: 감지된 영상 데이터를 세션 단위로 로컬에 저장할 수 있다 | H15: Closed | I15: #58 | J15: 8 | K15: #57
A16: 15 | B16: Epic 2 | D16: 1 | E16: Epic | F16: 12 | G16: Epic 2: 분석 파이프라인 | H16: Closed | K16: #12
A17: 16 | B17: Epic 2 | C17: Story 2-1 | D17: 2 | E17: Story | F17: 13 | G17: Story 2-1: 30분 비활성 기준으로 세션 종료를 자동으로 감지할 수 있다 | H17: Closed | J17: 12 | K17: #13
A18: 17 | B18: Epic 2 | C18: Story 2-1 | D18: 3 | E18: Task | F18: 14 | G18: 마지막 시청 시각 갱신 로직 구현 | H18: Closed | J18: 13 | K18: #14
A19: 18 | B19: Epic 2 | C19: Story 2-1 | D19: 3 | E19: Task | F19: 15 | G19: 30분 타임아웃 감지 및 세션 종료 트리거 구현 | H19: Closed | J19: 13 | K19: #15
A20: 19 | B20: Epic 2 | C20: Story 2-1 | D20: 3 | E20: Task | F20: 16 | G20: 세션 시작/종료 시간 및 세션 ID 기록 로직 구현 | H20: Closed | J20: 13 | K20: #16
A21: 20 | B21: Epic 2 | C21: Story 2-1 | D21: 3 | E21: Task | F21: 59 | G21: feat: 30분 비활성 기준으로 세션 종료를 자동으로 감지할 수 있다 | H21: Closed | I21: #60 | J21: 13 | K21: #59
A22: 21 | B22: Epic 2 | C22: Story 2-1 | D22: 3 | E22: Bug | F22: 93 | G22: fix: Service worker가 비활성 상태에서 영상이 세션이 기록되지 않는 문제 | H22: Closed | I22: #94 | J22: 13 | K22: #93
A23: 22 | B23: Epic 2 | C23: Story 2-2 | D23: 2 | E23: Story | F23: 17 | G23: Story 2-2: 영상 ID로 YouTube Data API를 통해 카테고리 정보를 조회할 수 있다 | H23: Closed | J23: 12 | K23: #17
A24: 23 | B24: Epic 2 | C24: Story 2-2 | D24: 3 | E24: Task | F24: 18 | G24: YouTube Data API v3 키 발급 및 환경 설정 | H24: Closed | J24: 17 | K24: #18
A25: 24 | B25: Epic 2 | C25: Story 2-2 | D25: 3 | E25: Task | F25: 19 | G25: videos.list API 호출 함수 구현 | H25: Closed | J25: 17 | K25: #19
A26: 25 | B26: Epic 2 | C26: Story 2-2 | D26: 3 | E26: Task | F26: 20 | G26: categoryId → 카테고리명 매핑 테이블 작성 | H26: Closed | J26: 17 | K26: #20
A27: 26 | B27: Epic 2 | C27: Story 2-2 | D27: 3 | E27: Task | F27: 21 | G27: API 에러 처리 및 할당량 초과 대응 로직 구현 | H27: Closed | J27: 17 | K27: #21
A28: 27 | B28: Epic 2 | C28: Story 2-2 | D28: 3 | E28: Task | F28: 61 | G28: feat: 영상 ID로 YouTube Data API를 통해 카테고리 정보를 조회할 수 있다 | H28: Closed | I28: #62 | J28: 17 | K28: #61
A29: 28 | B29: Epic 2 | C29: Story 2-3 | D29: 2 | E29: Story | F29: 22 | G29: Story 2-3: 세션별 카테고리 분포를 Shannon Entropy로 계산할 수 있다 | H29: Closed | J29: 12 | K29: #22
A30: 29 | B30: Epic 2 | C30: Story 2-3 | D30: 3 | E30: Task | F30: 23 | G30: 카테고리별 비율 계산 함수 구현 | H30: Closed | J30: 22 | K30: #23
A31: 30 | B31: Epic 2 | C31: Story 2-3 | D31: 3 | E31: Task | F31: 24 | G31: Shannon Entropy 계산 함수 구현 | H31: Closed | J31: 22 | K31: #24
A32: 31 | B32: Epic 2 | C32: Story 2-3 | D32: 3 | E32: Task | F32: 25 | G32: 세션 분석 결과 데이터 구조 정의 및 storage 저장 | H32: Closed | J32: 22 | K32: #25
A33: 32 | B33: Epic 2 | C33: Story 2-3 | D33: 3 | E33: Task | F33: 63 | G33: feat: 세션별 카테고리 분포를 Shannon Entropy로 계산할 수 있다 | H33: Closed | I33: #64 | J33: 22 | K33: #63
A34: 33 | B34: Epic 2 | C34: Story 2-4 | D34: 2 | E34: Story | F34: 26 | G34: Story 2-4: LLM API를 통해 카테고리 분포 기반 자연어 리뷰를 자동 생성할 수 있다 | H34: Closed | J34: 12 | K34: #26
A35: 34 | B35: Epic 2 | C35: Story 2-4 | D35: 3 | E35: Task | F35: 27 | G35: LLM API 선택 및 키 발급 | H35: Closed | J35: 26 | K35: #27
A36: 35 | B36: Epic 2 | C36: Story 2-4 | D36: 3 | E36: Task | F36: 28 | G36: 카테고리 분포를 LLM 프롬프트로 변환하는 함수 구현 | H36: Closed | J36: 26 | K36: #28
A37: 36 | B37: Epic 2 | C37: Story 2-4 | D37: 3 | E37: Task | F37: 29 | G37: LLM API 호출 및 응답 파싱 함수 구현 | H37: Closed | J37: 26 | K37: #29
A38: 37 | B38: Epic 2 | C38: Story 2-4 | D38: 3 | E38: Task | F38: 30 | G38: 리뷰 생성 실패 시 폴백 처리 구현 | H38: Closed | J38: 26 | K38: #30
A39: 38 | B39: Epic 2 | C39: Story 2-4 | D39: 3 | E39: Task | F39: 65 | G39: feat: LLM API를 통해 카테고리 분포 기반 자연어 리뷰를 자동 생성할 수 있다 | H39: Closed | I39: #66 | J39: 26 | K39: #65
A40: 39 | B40: Epic 2 | C40: Story 2-4 | D40: 3 | E40: Task | F40: 102 | G40: feat: 시청 패턴 변화 기반 연구 맞춤형 피드백 생성 | H40: Closed | I40: #103 | J40: 26 | K40: #102
...

Sheet 에픽별 요약
A1: Epic | B1: 제목 | C1: Story 수 | D1: Task 수 | E1: Bug 수 | F1: 전체 이슈 | G1: Open | H1: Closed | I1: 완료율
A2: Epic 1 | B2: Epic 1: 크롬 확장 프로그램 - 핵심 데이터 수집 | C2: =COUNTIFS(백로그!$B$2:$B$170,$A2,백로그!$E$2:$E$170,"Story") | D2: =COUNTIFS(백로그!$B$2:$B$170,$A2,백로그!$E$2:$E$170,"Task") | E2: =COUNTIFS(백로그!$B$2:$B$170,$A2,백로그!$E$2:$E$170,"Bug") | F2: =SUM(C2:E2) | G2: =COUNTIFS(백로그!$B$2:$B$170,$A2,백로그!$H$2:$H$170,"Open",백로그!$E$2:$E$170,"<>Epic") | H2: =COUNTIFS(백로그!$B$2:$B$170,$A2,백로그!$H$2:$H$170,"Closed",백로그!$E$2:$E$170,"<>Epic") | I2: =IF(F2=0,0,H2/F2)
A3: Epic 2 | B3: Epic 2: 분석 파이프라인 | C3: =COUNTIFS(백로그!$B$2:$B$170,$A3,백로그!$E$2:$E$170,"Story") | D3: =COUNTIFS(백로그!$B$2:$B$170,$A3,백로그!$E$2:$E$170,"Task") | E3: =COUNTIFS(백로그!$B$2:$B$170,$A3,백로그!$E$2:$E$170,"Bug") | F3: =SUM(C3:E3) | G3: =COUNTIFS(백로그!$B$2:$B$170,$A3,백로그!$H$2:$H$170,"Open",백로그!$E$2:$E$170,"<>Epic") | H3: =COUNTIFS(백로그!$B$2:$B$170,$A3,백로그!$H$2:$H$170,"Closed",백로그!$E$2:$E$170,"<>Epic") | I3: =IF(F3=0,0,H3/F3)
A4: Epic 3 | B4: Epic 3: 팝업 UI & 시각화 | C4: =COUNTIFS(백로그!$B$2:$B$170,$A4,백로그!$E$2:$E$170,"Story") | D4: =COUNTIFS(백로그!$B$2:$B$170,$A4,백로그!$E$2:$E$170,"Task") | E4: =COUNTIFS(백로그!$B$2:$B$170,$A4,백로그!$E$2:$E$170,"Bug") | F4: =SUM(C4:E4) | G4: =COUNTIFS(백로그!$B$2:$B$170,$A4,백로그!$H$2:$H$170,"Open",백로그!$E$2:$E$170,"<>Epic") | H4: =COUNTIFS(백로그!$B$2:$B$170,$A4,백로그!$H$2:$H$170,"Closed",백로그!$E$2:$E$170,"<>Epic") | I4: =IF(F4=0,0,H4/F4)
A5: Epic 4 | B5: Epic 4: 백엔드 서버 - API & DB | C5: =COUNTIFS(백로그!$B$2:$B$170,$A5,백로그!$E$2:$E$170,"Story") | D5: =COUNTIFS(백로그!$B$2:$B$170,$A5,백로그!$E$2:$E$170,"Task") | E5: =COUNTIFS(백로그!$B$2:$B$170,$A5,백로그!$E$2:$E$170,"Bug") | F5: =SUM(C5:E5) | G5: =COUNTIFS(백로그!$B$2:$B$170,$A5,백로그!$H$2:$H$170,"Open",백로그!$E$2:$E$170,"<>Epic") | H5: =COUNTIFS(백로그!$B$2:$B$170,$A5,백로그!$H$2:$H$170,"Closed",백로그!$E$2:$E$170,"<>Epic") | I5: =IF(F5=0,0,H5/F5)
A6: Epic 5 | B6: Epic 5: 데이터·개인정보 보강 | C6: =COUNTIFS(백로그!$B$2:$B$170,$A6,백로그!$E$2:$E$170,"Story") | D6: =COUNTIFS(백로그!$B$2:$B$170,$A6,백로그!$E$2:$E$170,"Task") | E6: =COUNTIFS(백로그!$B$2:$B$170,$A6,백로그!$E$2:$E$170,"Bug") | F6: =SUM(C6:E6) | G6: =COUNTIFS(백로그!$B$2:$B$170,$A6,백로그!$H$2:$H$170,"Open",백로그!$E$2:$E$170,"<>Epic") | H6: =COUNTIFS(백로그!$B$2:$B$170,$A6,백로그!$H$2:$H$170,"Closed",백로그!$E$2:$E$170,"<>Epic") | I6: =IF(F6=0,0,H6/F6)
A7: Epic 6 | B7: Epic 6. 본 연구 착수 전 기능 안정화 | C7: =COUNTIFS(백로그!$B$2:$B$170,$A7,백로그!$E$2:$E$170,"Story") | D7: =COUNTIFS(백로그!$B$2:$B$170,$A7,백로그!$E$2:$E$170,"Task") | E7: =COUNTIFS(백로그!$B$2:$B$170,$A7,백로그!$E$2:$E$170,"Bug") | F7: =SUM(C7:E7) | G7: =COUNTIFS(백로그!$B$2:$B$170,$A7,백로그!$H$2:$H$170,"Open",백로그!$E$2:$E$170,"<>Epic") | H7: =COUNTIFS(백로그!$B$2:$B$170,$A7,백로그!$H$2:$H$170,"Closed",백로그!$E$2:$E$170,"<>Epic") | I7: =IF(F7=0,0,H7/F7)
A8: Epic 7 | B8: Epic 7. 관측 체계 구축 및 운영 | C8: =COUNTIFS(백로그!$B$2:$B$170,$A8,백로그!$E$2:$E$170,"Story") | D8: =COUNTIFS(백로그!$B$2:$B$170,$A8,백로그!$E$2:$E$170,"Task") | E8: =COUNTIFS(백로그!$B$2:$B$170,$A8,백로그!$E$2:$E$170,"Bug") | F8: =SUM(C8:E8) | G8: =COUNTIFS(백로그!$B$2:$B$170,$A8,백로그!$H$2:$H$170,"Open",백로그!$E$2:$E$170,"<>Epic") | H8: =COUNTIFS(백로그!$B$2:$B$170,$A8,백로그!$H$2:$H$170,"Closed",백로그!$E$2:$E$170,"<>Epic") | I8: =IF(F8=0,0,H8/F8)
A9: Epic 8 | B9: Epic 8. 본 연구 착수 전 IRB 정합성 확보 및 시스템 정비 | C9: =COUNTIFS(백로그!$B$2:$B$170,$A9,백로그!$E$2:$E$170,"Story") | D9: =COUNTIFS(백로그!$B$2:$B$170,$A9,백로그!$E$2:$E$170,"Task") | E9: =COUNTIFS(백로그!$B$2:$B$170,$A9,백로그!$E$2:$E$170,"Bug") | F9: =SUM(C9:E9) | G9: =COUNTIFS(백로그!$B$2:$B$170,$A9,백로그!$H$2:$H$170,"Open",백로그!$E$2:$E$170,"<>Epic") | H9: =COUNTIFS(백로그!$B$2:$B$170,$A9,백로그!$H$2:$H$170,"Closed",백로그!$E$2:$E$170,"<>Epic") | I9: =IF(F9=0,0,H9/F9)
A10: Epic 9 | B10: Epic 9. 테스트 및 품질 보강 | C10: =COUNTIFS(백로그!$B$2:$B$170,$A10,백로그!$E$2:$E$170,"Story") | D10: =COUNTIFS(백로그!$B$2:$B$170,$A10,백로그!$E$2:$E$170,"Task") | E10: =COUNTIFS(백로그!$B$2:$B$170,$A10,백로그!$E$2:$E$170,"Bug") | F10: =SUM(C10:E10) | G10: =COUNTIFS(백로그!$B$2:$B$170,$A10,백로그!$H$2:$H$170,"Open",백로그!$E$2:$E$170,"<>Epic") | H10: =COUNTIFS(백로그!$B$2:$B$170,$A10,백로그!$H$2:$H$170,"Closed",백로그!$E$2:$E$170,"<>Epic") | I10: =IF(F10=0,0,H10/F10)
A11: 합계 | C11: =SUM(C2:C10) | D11: =SUM(D2:D10) | E11: =SUM(E2:E10) | F11: =SUM(F2:F10) | G11: =SUM(G2:G10) | H11: =SUM(H2:H10) | I11: =IF(F11=0,0,H11/F11)

Sheet 미분류·확인 필요
A1: 이슈 # | B1: 제목 | C1: 상태 | D1: 제안 위치 | E1: 비고 | F1: 링크
A2: 75 | B2: feat: 실험 온보딩 및 설문 알림 기능을 사용할 수 있다 | C2: Closed | D2: #49 하위 Task | E2: PR #76. #49와 쌍둥이 작업 이슈 | F2: #75
A3: 115 | B3: 개인정보·식별자 체계 및 IRB / 개인정보 처리방침 재설계 | C3: Closed | D3: #128 하위 Task | E3: PR #120. Story 5-1의 1차 작업 | F3: #115
A4: 269 | B4: bug: 4xx 접근 로그 추가 및 그 과정에서 발견한 보안·데이터 정합성 수정 | C4: Closed | D4: #172 Story 7-1 하위 Bug | E4: 제목 접두어 fix: 로 변경 권장 | F4: #269
A5: 91 | B5: feat: 세션 분석 완료 후 서버 전송 | C5: Closed | D5: 중복으로 닫기 | E5: #89와 본문 동일 | F5: #91
A6: 97 | B6: 2차 개발 작업 리스트 및 폴더 구조 정리 | C6: Closed | D6: 부모 없음 | E6: 프로젝트 관리 작업, PR #98 | F6: #97
A7: 77 | B7: Story 4-4: 서버를 외부에 배포하여 확장 프로그램과 통신할 수 있다 | C7: Closed | D7: 중복으로 닫기 | E7: #78(Story 4-3)과 제목 동일, 부모 없음 | F7: #77
